NEW CRON JOB
NEW CRON JOB
NEW CRON JOB
NEW CRON JOB
NEW CRON JOB
NEW CRON JOB
NEW CRON JOB
NEW CRON JOB
Traceback (most recent call last):
  File "/home/rob/Documents/University23-24/Term_2/Group_Software_Engineering_Project/Project/sustainability_project/manage.py", line 22, in <module>
    main()
  File "/home/rob/Documents/University23-24/Term_2/Group_Software_Engineering_Project/Project/sustainability_project/manage.py", line 18, in main
    execute_from_command_line(sys.argv)
  File "/home/rob/.local/lib/python3.10/site-packages/django/core/management/__init__.py", line 442, in execute_from_command_line
    utility.execute()
  File "/home/rob/.local/lib/python3.10/site-packages/django/core/management/__init__.py", line 436, in execute
    self.fetch_command(subcommand).run_from_argv(self.argv)
  File "/home/rob/.local/lib/python3.10/site-packages/django/core/management/base.py", line 412, in run_from_argv
    self.execute(*args, **cmd_options)
  File "/home/rob/.local/lib/python3.10/site-packages/django/core/management/base.py", line 458, in execute
    output = self.handle(*args, **options)
  File "/home/rob/.local/lib/python3.10/site-packages/django_crontab/management/commands/crontab.py", line 29, in handle
    Crontab().run_job(options['jobhash'])
  File "/home/rob/.local/lib/python3.10/site-packages/django_crontab/crontab.py", line 142, in run_job
    module = import_module(module_path)
  File "/usr/lib/python3.10/importlib/__init__.py", line 126, in import_module
    return _bootstrap._gcd_import(name[level:], package, level)
  File "<frozen importlib._bootstrap>", line 1050, in _gcd_import
  File "<frozen importlib._bootstrap>", line 1027, in _find_and_load
  File "<frozen importlib._bootstrap>", line 1006, in _find_and_load_unlocked
  File "<frozen importlib._bootstrap>", line 688, in _load_unlocked
  File "<frozen importlib._bootstrap_external>", line 883, in exec_module
  File "<frozen importlib._bootstrap>", line 241, in _call_with_frames_removed
  File "/home/rob/Documents/University23-24/Term_2/Group_Software_Engineering_Project/Project/sustainability_project/project/cron.py", line 1, in <module>
    from models import Challenge, ChallengesAssigned
ModuleNotFoundError: No module named 'models'
Traceback (most recent call last):
  File "/home/rob/Documents/University23-24/Term_2/Group_Software_Engineering_Project/Project/sustainability_project/manage.py", line 22, in <module>
    main()
  File "/home/rob/Documents/University23-24/Term_2/Group_Software_Engineering_Project/Project/sustainability_project/manage.py", line 18, in main
    execute_from_command_line(sys.argv)
  File "/home/rob/.local/lib/python3.10/site-packages/django/core/management/__init__.py", line 442, in execute_from_command_line
    utility.execute()
  File "/home/rob/.local/lib/python3.10/site-packages/django/core/management/__init__.py", line 436, in execute
    self.fetch_command(subcommand).run_from_argv(self.argv)
  File "/home/rob/.local/lib/python3.10/site-packages/django/core/management/base.py", line 412, in run_from_argv
    self.execute(*args, **cmd_options)
  File "/home/rob/.local/lib/python3.10/site-packages/django/core/management/base.py", line 458, in execute
    output = self.handle(*args, **options)
  File "/home/rob/.local/lib/python3.10/site-packages/django_crontab/management/commands/crontab.py", line 29, in handle
    Crontab().run_job(options['jobhash'])
  File "/home/rob/.local/lib/python3.10/site-packages/django_crontab/crontab.py", line 142, in run_job
    module = import_module(module_path)
  File "/usr/lib/python3.10/importlib/__init__.py", line 126, in import_module
    return _bootstrap._gcd_import(name[level:], package, level)
  File "<frozen importlib._bootstrap>", line 1050, in _gcd_import
  File "<frozen importlib._bootstrap>", line 1027, in _find_and_load
  File "<frozen importlib._bootstrap>", line 1006, in _find_and_load_unlocked
  File "<frozen importlib._bootstrap>", line 688, in _load_unlocked
  File "<frozen importlib._bootstrap_external>", line 883, in exec_module
  File "<frozen importlib._bootstrap>", line 241, in _call_with_frames_removed
  File "/home/rob/Documents/University23-24/Term_2/Group_Software_Engineering_Project/Project/sustainability_project/project/cron.py", line 1, in <module>
    from models import Challenge, ChallengesAssigned
ModuleNotFoundError: No module named 'models'
Failed to complete cronjob at ('* * * * *', 'project.cron.get_new_daily_challenge', '>> /home/rob/Documents/University23-24/Term_2/Group_Software_Engineering_Project/Project/sustainability_project/cron_log.log 2>&1 ')
Traceback (most recent call last):
  File "/home/rob/.local/lib/python3.10/site-packages/django_crontab/crontab.py", line 145, in run_job
    func(*job_args, **job_kwargs)
  File "/home/rob/Documents/University23-24/Term_2/Group_Software_Engineering_Project/Project/sustainability_project/project/cron.py", line 8, in get_new_daily_challenge
    random_challenge = random.choice(all_challenges)
  File "/usr/lib/python3.10/random.py", line 378, in choice
    return seq[self._randbelow(len(seq))]
IndexError: list index out of range
=== STARTING CRON ===
Failed to complete cronjob at ('* * * * *', 'project.cron.get_new_daily_challenge', '>> /home/rob/Documents/University23-24/Term_2/Group_Software_Engineering_Project/Project/sustainability_project/cron_log.log 2>&1 ')
Traceback (most recent call last):
  File "/home/rob/.local/lib/python3.10/site-packages/django_crontab/crontab.py", line 145, in run_job
    func(*job_args, **job_kwargs)
  File "/home/rob/Documents/University23-24/Term_2/Group_Software_Engineering_Project/Project/sustainability_project/project/cron.py", line 8, in get_new_daily_challenge
    random_challenge = random.choice(all_challenges)
  File "/usr/lib/python3.10/random.py", line 378, in choice
    return seq[self._randbelow(len(seq))]
IndexError: list index out of range
=== STARTING CRON ===
Failed to complete cronjob at ('* * * * *', 'project.cron.get_new_daily_challenge', '>> /home/rob/Documents/University23-24/Term_2/Group_Software_Engineering_Project/Project/sustainability_project/cron_log.log 2>&1 ')
Traceback (most recent call last):
  File "/home/rob/.local/lib/python3.10/site-packages/django_crontab/crontab.py", line 145, in run_job
    func(*job_args, **job_kwargs)
  File "/home/rob/Documents/University23-24/Term_2/Group_Software_Engineering_Project/Project/sustainability_project/project/cron.py", line 8, in get_new_daily_challenge
    random_challenge = random.choice(all_challenges)
  File "/usr/lib/python3.10/random.py", line 378, in choice
    return seq[self._randbelow(len(seq))]
IndexError: list index out of range
=== STARTING CRON ===
Failed to complete cronjob at ('* * * * *', 'project.cron.get_new_daily_challenge', '>> /home/rob/Documents/University23-24/Term_2/Group_Software_Engineering_Project/Project/sustainability_project/cron_log.log 2>&1 ')
Traceback (most recent call last):
  File "/home/rob/.local/lib/python3.10/site-packages/django_crontab/crontab.py", line 145, in run_job
    func(*job_args, **job_kwargs)
  File "/home/rob/Documents/University23-24/Term_2/Group_Software_Engineering_Project/Project/sustainability_project/project/cron.py", line 8, in get_new_daily_challenge
    random_challenge = random.choice(all_challenges)
  File "/usr/lib/python3.10/random.py", line 378, in choice
    return seq[self._randbelow(len(seq))]
IndexError: list index out of range
=== STARTING CRON ===
Failed to complete cronjob at ('* * * * *', 'project.cron.get_new_daily_challenge', '>> /home/rob/Documents/University23-24/Term_2/Group_Software_Engineering_Project/Project/sustainability_project/cron_log.log 2>&1 ')
Traceback (most recent call last):
  File "/home/rob/.local/lib/python3.10/site-packages/django_crontab/crontab.py", line 145, in run_job
    func(*job_args, **job_kwargs)
  File "/home/rob/Documents/University23-24/Term_2/Group_Software_Engineering_Project/Project/sustainability_project/project/cron.py", line 8, in get_new_daily_challenge
    random_challenge = random.choice(all_challenges)
  File "/usr/lib/python3.10/random.py", line 378, in choice
    return seq[self._randbelow(len(seq))]
IndexError: list index out of range
=== STARTING CRON ===
Failed to complete cronjob at ('* * * * *', 'project.cron.get_new_daily_challenge', '>> /home/rob/Documents/University23-24/Term_2/Group_Software_Engineering_Project/Project/sustainability_project/cron_log.log 2>&1 ')
Traceback (most recent call last):
  File "/home/rob/.local/lib/python3.10/site-packages/django_crontab/crontab.py", line 145, in run_job
    func(*job_args, **job_kwargs)
  File "/home/rob/Documents/University23-24/Term_2/Group_Software_Engineering_Project/Project/sustainability_project/project/cron.py", line 8, in get_new_daily_challenge
    random_challenge = random.choice(all_challenges)
  File "/usr/lib/python3.10/random.py", line 378, in choice
    return seq[self._randbelow(len(seq))]
IndexError: list index out of range
=== STARTING CRON ===
Failed to complete cronjob at ('* * * * *', 'project.cron.get_new_daily_challenge', '>> /home/rob/Documents/University23-24/Term_2/Group_Software_Engineering_Project/Project/sustainability_project/cron_log.log 2>&1 ')
Traceback (most recent call last):
  File "/home/rob/.local/lib/python3.10/site-packages/django_crontab/crontab.py", line 145, in run_job
    func(*job_args, **job_kwargs)
  File "/home/rob/Documents/University23-24/Term_2/Group_Software_Engineering_Project/Project/sustainability_project/project/cron.py", line 8, in get_new_daily_challenge
    random_challenge = random.choice(all_challenges)
  File "/usr/lib/python3.10/random.py", line 378, in choice
    return seq[self._randbelow(len(seq))]
IndexError: list index out of range
=== STARTING CRON ===
Failed to complete cronjob at ('* * * * *', 'project.cron.get_new_daily_challenge', '>> /home/rob/Documents/University23-24/Term_2/Group_Software_Engineering_Project/Project/sustainability_project/cron_log.log 2>&1 ')
Traceback (most recent call last):
  File "/home/rob/.local/lib/python3.10/site-packages/django_crontab/crontab.py", line 145, in run_job
    func(*job_args, **job_kwargs)
  File "/home/rob/Documents/University23-24/Term_2/Group_Software_Engineering_Project/Project/sustainability_project/project/cron.py", line 8, in get_new_daily_challenge
    random_challenge = random.choice(all_challenges)
  File "/usr/lib/python3.10/random.py", line 378, in choice
    return seq[self._randbelow(len(seq))]
IndexError: list index out of range
=== STARTING CRON ===
Failed to complete cronjob at ('* * * * *', 'project.cron.get_new_daily_challenge', '>> /home/rob/Documents/University23-24/Term_2/Group_Software_Engineering_Project/Project/sustainability_project/cron_log.log 2>&1 ')
Traceback (most recent call last):
  File "/home/rob/.local/lib/python3.10/site-packages/django_crontab/crontab.py", line 145, in run_job
    func(*job_args, **job_kwargs)
  File "/home/rob/Documents/University23-24/Term_2/Group_Software_Engineering_Project/Project/sustainability_project/project/cron.py", line 8, in get_new_daily_challenge
    random_challenge = random.choice(all_challenges)
  File "/usr/lib/python3.10/random.py", line 378, in choice
    return seq[self._randbelow(len(seq))]
IndexError: list index out of range
=== STARTING CRON ===
Failed to complete cronjob at ('* * * * *', 'project.cron.get_new_daily_challenge', '>> /home/rob/Documents/University23-24/Term_2/Group_Software_Engineering_Project/Project/sustainability_project/cron_log.log 2>&1 ')
Traceback (most recent call last):
  File "/home/rob/.local/lib/python3.10/site-packages/django_crontab/crontab.py", line 145, in run_job
    func(*job_args, **job_kwargs)
  File "/home/rob/Documents/University23-24/Term_2/Group_Software_Engineering_Project/Project/sustainability_project/project/cron.py", line 8, in get_new_daily_challenge
    random_challenge = random.choice(all_challenges)
  File "/usr/lib/python3.10/random.py", line 378, in choice
    return seq[self._randbelow(len(seq))]
IndexError: list index out of range
=== STARTING CRON ===
=== STARTING CRON ===
=== ENDING CRON ===
=== STARTING CRON ===
=== ENDING CRON ===
=== STARTING CRON ===
=== ENDING CRON ===
Traceback (most recent call last):
  File "/home/rob/Documents/University23-24/Term_2/Group_Software_Engineering_Project/Project/sustainability_project/manage.py", line 22, in <module>
    main()
  File "/home/rob/Documents/University23-24/Term_2/Group_Software_Engineering_Project/Project/sustainability_project/manage.py", line 18, in main
    execute_from_command_line(sys.argv)
  File "/home/rob/.local/lib/python3.10/site-packages/django/core/management/__init__.py", line 442, in execute_from_command_line
    utility.execute()
  File "/home/rob/.local/lib/python3.10/site-packages/django/core/management/__init__.py", line 436, in execute
    self.fetch_command(subcommand).run_from_argv(self.argv)
  File "/home/rob/.local/lib/python3.10/site-packages/django/core/management/base.py", line 412, in run_from_argv
    self.execute(*args, **cmd_options)
  File "/home/rob/.local/lib/python3.10/site-packages/django/core/management/base.py", line 458, in execute
    output = self.handle(*args, **options)
  File "/home/rob/.local/lib/python3.10/site-packages/django_crontab/management/commands/crontab.py", line 29, in handle
    Crontab().run_job(options['jobhash'])
  File "/home/rob/.local/lib/python3.10/site-packages/django_crontab/crontab.py", line 142, in run_job
    module = import_module(module_path)
  File "/usr/lib/python3.10/importlib/__init__.py", line 126, in import_module
    return _bootstrap._gcd_import(name[level:], package, level)
  File "<frozen importlib._bootstrap>", line 1050, in _gcd_import
  File "<frozen importlib._bootstrap>", line 1027, in _find_and_load
  File "<frozen importlib._bootstrap>", line 1006, in _find_and_load_unlocked
  File "<frozen importlib._bootstrap>", line 688, in _load_unlocked
  File "<frozen importlib._bootstrap_external>", line 879, in exec_module
  File "<frozen importlib._bootstrap_external>", line 1017, in get_code
  File "<frozen importlib._bootstrap_external>", line 947, in source_to_code
  File "<frozen importlib._bootstrap>", line 241, in _call_with_frames_removed
  File "/home/rob/Documents/University23-24/Term_2/Group_Software_Engineering_Project/Project/sustainability_project/project/cron.py", line 11
    print(f"{new_daily_challenge.date_assigned.strftime("%d/%m/%Y")} {new_daily_challenge.challenge.title}")
                                                         ^
SyntaxError: f-string: unmatched '('
Traceback (most recent call last):
  File "/home/rob/Documents/University23-24/Term_2/Group_Software_Engineering_Project/Project/sustainability_project/manage.py", line 22, in <module>
    main()
  File "/home/rob/Documents/University23-24/Term_2/Group_Software_Engineering_Project/Project/sustainability_project/manage.py", line 18, in main
    execute_from_command_line(sys.argv)
  File "/home/rob/.local/lib/python3.10/site-packages/django/core/management/__init__.py", line 442, in execute_from_command_line
    utility.execute()
  File "/home/rob/.local/lib/python3.10/site-packages/django/core/management/__init__.py", line 436, in execute
    self.fetch_command(subcommand).run_from_argv(self.argv)
  File "/home/rob/.local/lib/python3.10/site-packages/django/core/management/base.py", line 412, in run_from_argv
    self.execute(*args, **cmd_options)
  File "/home/rob/.local/lib/python3.10/site-packages/django/core/management/base.py", line 458, in execute
    output = self.handle(*args, **options)
  File "/home/rob/.local/lib/python3.10/site-packages/django_crontab/management/commands/crontab.py", line 29, in handle
    Crontab().run_job(options['jobhash'])
  File "/home/rob/.local/lib/python3.10/site-packages/django_crontab/crontab.py", line 142, in run_job
    module = import_module(module_path)
  File "/usr/lib/python3.10/importlib/__init__.py", line 126, in import_module
    return _bootstrap._gcd_import(name[level:], package, level)
  File "<frozen importlib._bootstrap>", line 1050, in _gcd_import
  File "<frozen importlib._bootstrap>", line 1027, in _find_and_load
  File "<frozen importlib._bootstrap>", line 1006, in _find_and_load_unlocked
  File "<frozen importlib._bootstrap>", line 688, in _load_unlocked
  File "<frozen importlib._bootstrap_external>", line 879, in exec_module
  File "<frozen importlib._bootstrap_external>", line 1017, in get_code
  File "<frozen importlib._bootstrap_external>", line 947, in source_to_code
  File "<frozen importlib._bootstrap>", line 241, in _call_with_frames_removed
  File "/home/rob/Documents/University23-24/Term_2/Group_Software_Engineering_Project/Project/sustainability_project/project/cron.py", line 11
    print(f"{new_daily_challenge.date_assigned.strftime("%d/%m/%Y")} {new_daily_challenge.challenge.title}")
                                                         ^
SyntaxError: f-string: unmatched '('
Traceback (most recent call last):
  File "/home/rob/Documents/University23-24/Term_2/Group_Software_Engineering_Project/Project/sustainability_project/manage.py", line 22, in <module>
    main()
  File "/home/rob/Documents/University23-24/Term_2/Group_Software_Engineering_Project/Project/sustainability_project/manage.py", line 18, in main
    execute_from_command_line(sys.argv)
  File "/home/rob/.local/lib/python3.10/site-packages/django/core/management/__init__.py", line 442, in execute_from_command_line
    utility.execute()
  File "/home/rob/.local/lib/python3.10/site-packages/django/core/management/__init__.py", line 436, in execute
    self.fetch_command(subcommand).run_from_argv(self.argv)
  File "/home/rob/.local/lib/python3.10/site-packages/django/core/management/base.py", line 412, in run_from_argv
    self.execute(*args, **cmd_options)
  File "/home/rob/.local/lib/python3.10/site-packages/django/core/management/base.py", line 458, in execute
    output = self.handle(*args, **options)
  File "/home/rob/.local/lib/python3.10/site-packages/django_crontab/management/commands/crontab.py", line 29, in handle
    Crontab().run_job(options['jobhash'])
  File "/home/rob/.local/lib/python3.10/site-packages/django_crontab/crontab.py", line 142, in run_job
    module = import_module(module_path)
  File "/usr/lib/python3.10/importlib/__init__.py", line 126, in import_module
    return _bootstrap._gcd_import(name[level:], package, level)
  File "<frozen importlib._bootstrap>", line 1050, in _gcd_import
  File "<frozen importlib._bootstrap>", line 1027, in _find_and_load
  File "<frozen importlib._bootstrap>", line 1006, in _find_and_load_unlocked
  File "<frozen importlib._bootstrap>", line 688, in _load_unlocked
  File "<frozen importlib._bootstrap_external>", line 879, in exec_module
  File "<frozen importlib._bootstrap_external>", line 1017, in get_code
  File "<frozen importlib._bootstrap_external>", line 947, in source_to_code
  File "<frozen importlib._bootstrap>", line 241, in _call_with_frames_removed
  File "/home/rob/Documents/University23-24/Term_2/Group_Software_Engineering_Project/Project/sustainability_project/project/cron.py", line 11
    print(f"{new_daily_challenge.date_assigned.strftime("%d/%m/%Y")} {new_daily_challenge.challenge.title}")
                                                         ^
SyntaxError: f-string: unmatched '('
=== STARTING CRON ===
2024-02-22: 10 minute walk
=== ENDING CRON ===
=== STARTING CRON ===
2024-02-22: 10 minute walk
=== ENDING CRON ===
=== STARTING CRON ===
2024-02-22: 10 minute walk
=== ENDING CRON ===
=== STARTING CRON ===
2024-02-22: 10 minute walk
=== ENDING CRON ===
=== STARTING CRON ===
2024-02-22: 10 minute walk
=== ENDING CRON ===
=== STARTING CRON ===
2024-02-22: 10 minute walk
=== ENDING CRON ===
Traceback (most recent call last):
  File "/home/rob/Documents/University23-24/Term_2/Group_Software_Engineering_Project/Project/sustainability_project/manage.py", line 22, in <module>
    main()
  File "/home/rob/Documents/University23-24/Term_2/Group_Software_Engineering_Project/Project/sustainability_project/manage.py", line 18, in main
    execute_from_command_line(sys.argv)
  File "/home/rob/.local/lib/python3.10/site-packages/django/core/management/__init__.py", line 442, in execute_from_command_line
    utility.execute()
  File "/home/rob/.local/lib/python3.10/site-packages/django/core/management/__init__.py", line 436, in execute
    self.fetch_command(subcommand).run_from_argv(self.argv)
  File "/home/rob/.local/lib/python3.10/site-packages/django/core/management/base.py", line 412, in run_from_argv
    self.execute(*args, **cmd_options)
  File "/home/rob/.local/lib/python3.10/site-packages/django/core/management/base.py", line 458, in execute
    output = self.handle(*args, **options)
  File "/home/rob/.local/lib/python3.10/site-packages/django_crontab/management/commands/crontab.py", line 29, in handle
    Crontab().run_job(options['jobhash'])
  File "/home/rob/.local/lib/python3.10/site-packages/django_crontab/crontab.py", line 126, in run_job
    job = self.__get_job_by_hash(job_hash)
  File "/home/rob/.local/lib/python3.10/site-packages/django_crontab/crontab.py", line 171, in __get_job_by_hash
    raise RuntimeError(
RuntimeError: No job with hash a869ea98924ee6414e7c330df130659b found. It seems the crontab is out of sync with your settings.CRONJOBS. Run "python manage.py crontab add" again to resolve this issue!
Traceback (most recent call last):
  File "/home/rob/Documents/University23-24/Term_2/Group_Software_Engineering_Project/Project/sustainability_project/manage.py", line 22, in <module>
    main()
  File "/home/rob/Documents/University23-24/Term_2/Group_Software_Engineering_Project/Project/sustainability_project/manage.py", line 18, in main
    execute_from_command_line(sys.argv)
  File "/home/rob/.local/lib/python3.10/site-packages/django/core/management/__init__.py", line 442, in execute_from_command_line
    utility.execute()
  File "/home/rob/.local/lib/python3.10/site-packages/django/core/management/__init__.py", line 436, in execute
    self.fetch_command(subcommand).run_from_argv(self.argv)
  File "/home/rob/.local/lib/python3.10/site-packages/django/core/management/base.py", line 412, in run_from_argv
    self.execute(*args, **cmd_options)
  File "/home/rob/.local/lib/python3.10/site-packages/django/core/management/base.py", line 458, in execute
    output = self.handle(*args, **options)
  File "/home/rob/.local/lib/python3.10/site-packages/django_crontab/management/commands/crontab.py", line 29, in handle
    Crontab().run_job(options['jobhash'])
  File "/home/rob/.local/lib/python3.10/site-packages/django_crontab/crontab.py", line 126, in run_job
    job = self.__get_job_by_hash(job_hash)
  File "/home/rob/.local/lib/python3.10/site-packages/django_crontab/crontab.py", line 171, in __get_job_by_hash
    raise RuntimeError(
RuntimeError: No job with hash a869ea98924ee6414e7c330df130659b found. It seems the crontab is out of sync with your settings.CRONJOBS. Run "python manage.py crontab add" again to resolve this issue!
Traceback (most recent call last):
  File "/home/rob/Documents/University23-24/Term_2/Group_Software_Engineering_Project/Project/sustainability_project/manage.py", line 22, in <module>
    main()
  File "/home/rob/Documents/University23-24/Term_2/Group_Software_Engineering_Project/Project/sustainability_project/manage.py", line 18, in main
    execute_from_command_line(sys.argv)
  File "/home/rob/.local/lib/python3.10/site-packages/django/core/management/__init__.py", line 442, in execute_from_command_line
    utility.execute()
  File "/home/rob/.local/lib/python3.10/site-packages/django/core/management/__init__.py", line 436, in execute
    self.fetch_command(subcommand).run_from_argv(self.argv)
  File "/home/rob/.local/lib/python3.10/site-packages/django/core/management/base.py", line 412, in run_from_argv
    self.execute(*args, **cmd_options)
  File "/home/rob/.local/lib/python3.10/site-packages/django/core/management/base.py", line 458, in execute
    output = self.handle(*args, **options)
  File "/home/rob/.local/lib/python3.10/site-packages/django_crontab/management/commands/crontab.py", line 29, in handle
    Crontab().run_job(options['jobhash'])
  File "/home/rob/.local/lib/python3.10/site-packages/django_crontab/crontab.py", line 126, in run_job
    job = self.__get_job_by_hash(job_hash)
  File "/home/rob/.local/lib/python3.10/site-packages/django_crontab/crontab.py", line 171, in __get_job_by_hash
    raise RuntimeError(
RuntimeError: No job with hash a869ea98924ee6414e7c330df130659b found. It seems the crontab is out of sync with your settings.CRONJOBS. Run "python manage.py crontab add" again to resolve this issue!
Traceback (most recent call last):
  File "/home/rob/Documents/University23-24/Term_2/Group_Software_Engineering_Project/Project/sustainability_project/manage.py", line 22, in <module>
    main()
  File "/home/rob/Documents/University23-24/Term_2/Group_Software_Engineering_Project/Project/sustainability_project/manage.py", line 18, in main
    execute_from_command_line(sys.argv)
  File "/home/rob/.local/lib/python3.10/site-packages/django/core/management/__init__.py", line 442, in execute_from_command_line
    utility.execute()
  File "/home/rob/.local/lib/python3.10/site-packages/django/core/management/__init__.py", line 436, in execute
    self.fetch_command(subcommand).run_from_argv(self.argv)
  File "/home/rob/.local/lib/python3.10/site-packages/django/core/management/base.py", line 412, in run_from_argv
    self.execute(*args, **cmd_options)
  File "/home/rob/.local/lib/python3.10/site-packages/django/core/management/base.py", line 458, in execute
    output = self.handle(*args, **options)
  File "/home/rob/.local/lib/python3.10/site-packages/django_crontab/management/commands/crontab.py", line 29, in handle
    Crontab().run_job(options['jobhash'])
  File "/home/rob/.local/lib/python3.10/site-packages/django_crontab/crontab.py", line 126, in run_job
    job = self.__get_job_by_hash(job_hash)
  File "/home/rob/.local/lib/python3.10/site-packages/django_crontab/crontab.py", line 171, in __get_job_by_hash
    raise RuntimeError(
RuntimeError: No job with hash a869ea98924ee6414e7c330df130659b found. It seems the crontab is out of sync with your settings.CRONJOBS. Run "python manage.py crontab add" again to resolve this issue!
Traceback (most recent call last):
  File "/home/rob/Documents/University23-24/Term_2/Group_Software_Engineering_Project/Project/sustainability_project/manage.py", line 22, in <module>
    main()
  File "/home/rob/Documents/University23-24/Term_2/Group_Software_Engineering_Project/Project/sustainability_project/manage.py", line 18, in main
    execute_from_command_line(sys.argv)
  File "/home/rob/.local/lib/python3.10/site-packages/django/core/management/__init__.py", line 442, in execute_from_command_line
    utility.execute()
  File "/home/rob/.local/lib/python3.10/site-packages/django/core/management/__init__.py", line 436, in execute
    self.fetch_command(subcommand).run_from_argv(self.argv)
  File "/home/rob/.local/lib/python3.10/site-packages/django/core/management/base.py", line 412, in run_from_argv
    self.execute(*args, **cmd_options)
  File "/home/rob/.local/lib/python3.10/site-packages/django/core/management/base.py", line 458, in execute
    output = self.handle(*args, **options)
  File "/home/rob/.local/lib/python3.10/site-packages/django_crontab/management/commands/crontab.py", line 29, in handle
    Crontab().run_job(options['jobhash'])
  File "/home/rob/.local/lib/python3.10/site-packages/django_crontab/crontab.py", line 126, in run_job
    job = self.__get_job_by_hash(job_hash)
  File "/home/rob/.local/lib/python3.10/site-packages/django_crontab/crontab.py", line 171, in __get_job_by_hash
    raise RuntimeError(
RuntimeError: No job with hash a869ea98924ee6414e7c330df130659b found. It seems the crontab is out of sync with your settings.CRONJOBS. Run "python manage.py crontab add" again to resolve this issue!
Traceback (most recent call last):
  File "/home/rob/Documents/University23-24/Term_2/Group_Software_Engineering_Project/Project/sustainability_project/manage.py", line 22, in <module>
    main()
  File "/home/rob/Documents/University23-24/Term_2/Group_Software_Engineering_Project/Project/sustainability_project/manage.py", line 18, in main
    execute_from_command_line(sys.argv)
  File "/home/rob/.local/lib/python3.10/site-packages/django/core/management/__init__.py", line 442, in execute_from_command_line
    utility.execute()
  File "/home/rob/.local/lib/python3.10/site-packages/django/core/management/__init__.py", line 436, in execute
    self.fetch_command(subcommand).run_from_argv(self.argv)
  File "/home/rob/.local/lib/python3.10/site-packages/django/core/management/base.py", line 412, in run_from_argv
    self.execute(*args, **cmd_options)
  File "/home/rob/.local/lib/python3.10/site-packages/django/core/management/base.py", line 458, in execute
    output = self.handle(*args, **options)
  File "/home/rob/.local/lib/python3.10/site-packages/django_crontab/management/commands/crontab.py", line 29, in handle
    Crontab().run_job(options['jobhash'])
  File "/home/rob/.local/lib/python3.10/site-packages/django_crontab/crontab.py", line 126, in run_job
    job = self.__get_job_by_hash(job_hash)
  File "/home/rob/.local/lib/python3.10/site-packages/django_crontab/crontab.py", line 171, in __get_job_by_hash
    raise RuntimeError(
RuntimeError: No job with hash a869ea98924ee6414e7c330df130659b found. It seems the crontab is out of sync with your settings.CRONJOBS. Run "python manage.py crontab add" again to resolve this issue!
Traceback (most recent call last):
  File "/home/rob/Documents/University23-24/Term_2/Group_Software_Engineering_Project/Project/sustainability_project/manage.py", line 22, in <module>
    main()
  File "/home/rob/Documents/University23-24/Term_2/Group_Software_Engineering_Project/Project/sustainability_project/manage.py", line 18, in main
    execute_from_command_line(sys.argv)
  File "/home/rob/.local/lib/python3.10/site-packages/django/core/management/__init__.py", line 442, in execute_from_command_line
    utility.execute()
  File "/home/rob/.local/lib/python3.10/site-packages/django/core/management/__init__.py", line 436, in execute
    self.fetch_command(subcommand).run_from_argv(self.argv)
  File "/home/rob/.local/lib/python3.10/site-packages/django/core/management/base.py", line 412, in run_from_argv
    self.execute(*args, **cmd_options)
  File "/home/rob/.local/lib/python3.10/site-packages/django/core/management/base.py", line 458, in execute
    output = self.handle(*args, **options)
  File "/home/rob/.local/lib/python3.10/site-packages/django_crontab/management/commands/crontab.py", line 29, in handle
    Crontab().run_job(options['jobhash'])
  File "/home/rob/.local/lib/python3.10/site-packages/django_crontab/crontab.py", line 126, in run_job
    job = self.__get_job_by_hash(job_hash)
  File "/home/rob/.local/lib/python3.10/site-packages/django_crontab/crontab.py", line 171, in __get_job_by_hash
    raise RuntimeError(
RuntimeError: No job with hash a869ea98924ee6414e7c330df130659b found. It seems the crontab is out of sync with your settings.CRONJOBS. Run "python manage.py crontab add" again to resolve this issue!
Traceback (most recent call last):
  File "/home/rob/Documents/University23-24/Term_2/Group_Software_Engineering_Project/Project/sustainability_project/manage.py", line 22, in <module>
    main()
  File "/home/rob/Documents/University23-24/Term_2/Group_Software_Engineering_Project/Project/sustainability_project/manage.py", line 18, in main
    execute_from_command_line(sys.argv)
  File "/home/rob/.local/lib/python3.10/site-packages/django/core/management/__init__.py", line 442, in execute_from_command_line
    utility.execute()
  File "/home/rob/.local/lib/python3.10/site-packages/django/core/management/__init__.py", line 436, in execute
    self.fetch_command(subcommand).run_from_argv(self.argv)
  File "/home/rob/.local/lib/python3.10/site-packages/django/core/management/base.py", line 412, in run_from_argv
    self.execute(*args, **cmd_options)
  File "/home/rob/.local/lib/python3.10/site-packages/django/core/management/base.py", line 458, in execute
    output = self.handle(*args, **options)
  File "/home/rob/.local/lib/python3.10/site-packages/django_crontab/management/commands/crontab.py", line 29, in handle
    Crontab().run_job(options['jobhash'])
  File "/home/rob/.local/lib/python3.10/site-packages/django_crontab/crontab.py", line 126, in run_job
    job = self.__get_job_by_hash(job_hash)
  File "/home/rob/.local/lib/python3.10/site-packages/django_crontab/crontab.py", line 171, in __get_job_by_hash
    raise RuntimeError(
RuntimeError: No job with hash a869ea98924ee6414e7c330df130659b found. It seems the crontab is out of sync with your settings.CRONJOBS. Run "python manage.py crontab add" again to resolve this issue!
